<?xml version="1.0" encoding="utf-8"?>
<!--
Modified from auto-generated original:
- Add xacro macros and properties.
- Add end effector

This URDF was automatically created by SolidWorks to URDF Exporter!
Originally created by Stephen Brawner (brawner@gmail.com) 
Commit Version: 1.6.0-1-g15f4949  Build Version: 1.6.7594.29634
For more information, please see http://wiki.ros.org/sw_urdf_exporter
-->
<robot xmlns:xacro="http://www.ros.org/wiki/xacro">
  
  <xacro:macro name="so_arm_100_5dof" params="prefix=''">

  <xacro:property
    name="meshes_file_directory"
    value="package://so_arm_100_description/models/so_arm_100_5dof/meshes"/>

  <link name="${prefix}base_link">
    <gazebo>
      <material>Gazebo/Grey</material>
    </gazebo>
  </link>
  <joint name="${prefix}base_link_joint" type="fixed">
    <parent link="${prefix}base_link"/>
    <child link="${prefix}Base"/>
    <origin xyz="0 0 0" rpy="0 0 0"/>
  </joint>

  <link name="${prefix}Base">
    <inertial>
      <origin
        xyz="-2.45960666746703E-07 0.0311418169687909 0.0175746661003382"
        rpy="0 0 0" />
      <mass
        value="0.193184127927598" />
      <inertia
        ixx="0.000137030709467877"
        ixy="2.10136126944992E-08"
        ixz="4.24087422551286E-09"
        iyy="0.000169089551209259"
        iyz="2.26514711036514E-05"
        izz="0.000145097720857224" />
    </inertial>
    <visual>
      <origin
        xyz="0 0 0"
        rpy="0 0 0" />
      <geometry>
        <mesh
          filename="${meshes_file_directory}/Base.STL" />
      </geometry>
      <material name="brightyellow" >
        <color rgba="1.0 0.9921568627450981 0.00392156862745098 1.0" />
      </material>
    </visual>
    <collision>
      <origin
        xyz="0 0 0"
        rpy="0 0 0" />
      <geometry>
        <mesh
          filename="${meshes_file_directory}/Base.STL" />
      </geometry>
    </collision>
  </link>

  <link name="${prefix}Shoulder_Rotation_Pitch">
    <inertial>
      <origin
        xyz="-9.07886224712597E-05 0.0590971820568318 0.031089016892169"
        rpy="0 0 0" />
      <mass
        value="0.119226314127197" />
      <inertia
        ixx="5.90408775624429E-05"
        ixy="4.90800532852998E-07"
        ixz="-5.90451772654387E-08"
        iyy="3.21498601038881E-05"
        iyz="-4.58026206663885E-06"
        izz="5.86058514263952E-05" />
    </inertial>
    <visual>
      <origin
        xyz="0 0 0"
        rpy="0 0 0" />
      <geometry>
        <mesh
          filename="${meshes_file_directory}/Shoulder_Rotation_Pitch.STL" />
      </geometry>
      <material name="brightyellow" >
        <color rgba="1.0 0.9921568627450981 0.00392156862745098 1.0" />
      </material>
    </visual>
    <collision>
      <origin
        xyz="0 0 0"
        rpy="0 0 0" />
      <geometry>
        <mesh
          filename="${meshes_file_directory}/Shoulder_Rotation_Pitch.STL" />
      </geometry>
    </collision>
  </link>
  <joint name="${prefix}Shoulder_Rotation" type="revolute">
    <origin
      xyz="0 -0.0452 0.0165"
      rpy="1.5708 0 0" />
    <parent
      link="${prefix}Base" />
    <child
      link="${prefix}Shoulder_Rotation_Pitch" />
    <axis
      xyz="0 -1 0" />
    <limit effort="1000" lower="-1.96" upper="1.96" velocity="5.0"/>
    <dynamics damping="0.1"/>
  </joint>

  <link name="${prefix}Upper_Arm">
    <inertial>
      <origin
        xyz="-1.7205170190925E-05 0.0701802156327694 0.00310545118155671"
        rpy="0 0 0" />
      <mass
        value="0.162409284599177" />
      <inertia
        ixx="0.000167153146617081"
        ixy="1.03902689187701E-06"
        ixz="-1.20161820645189E-08"
        iyy="7.01946992214245E-05"
        iyz="2.11884806298698E-06"
        izz="0.000213280241160769" />
    </inertial>
    <visual>
      <origin
        xyz="0 0 0"
        rpy="0 0 0" />
      <geometry>
        <mesh
          filename="${meshes_file_directory}/Upper_Arm.STL" />
      </geometry>
      <material name="brightyellow" >
        <color rgba="1.0 0.9921568627450981 0.00392156862745098 1.0" />
      </material>
    </visual>
    <collision>
      <origin
        xyz="0 0 0"
        rpy="0 0 0" />
      <geometry>
        <mesh
          filename="${meshes_file_directory}/Upper_Arm.STL" />
      </geometry>
    </collision>
  </link>
  <joint name="${prefix}Shoulder_Pitch" type="revolute">
    <origin
      xyz="0 0.1025 0.0306"
      rpy="0 0 0" />
    <parent
      link="${prefix}Shoulder_Rotation_Pitch" />
    <child
      link="${prefix}Upper_Arm" />
    <axis
      xyz="1 0 0" />
    <limit effort="1000" lower="-1.745" upper="1.745" velocity="5.0"/>
    <dynamics damping="0.1"/>
  </joint>

  <link name="${prefix}Lower_Arm">
    <inertial>
      <origin
        xyz="-0.00339603710186651 0.00137796353960074 0.0768006751156044"
        rpy="0 0 0" />
      <mass
        value="0.147967774582291" />
      <inertia
        ixx="0.000105333995841409"
        ixy="1.73059237226499E-07"
        ixz="-1.1720305455211E-05"
        iyy="0.000138766654485212"
        iyz="1.77429964684103E-06"
        izz="5.08741652515214E-05" />
    </inertial>
    <visual>
      <origin
        xyz="0 0 0"
        rpy="0 0 0" />
      <geometry>
        <mesh
          filename="${meshes_file_directory}/Lower_Arm.STL" />
      </geometry>
      <material name="brightyellow" >
        <color rgba="1.0 0.9921568627450981 0.00392156862745098 1.0" />
      </material>
    </visual>
    <collision>
      <origin
        xyz="0 0 0"
        rpy="0 0 0" />
      <geometry>
        <mesh
          filename="${meshes_file_directory}/Lower_Arm.STL" />
      </geometry>
    </collision>
  </link>
  <joint name="${prefix}Elbow" type="revolute">
    <origin
      xyz="0 0.11257 0.028"
      rpy="0 0 0" />
    <parent
      link="${prefix}Upper_Arm" />
    <child
      link="${prefix}Lower_Arm" />
    <axis
      xyz="1 0 0" />
    <limit effort="1000" lower="-1.5" upper="1.5" velocity="5.0"/>
    <dynamics damping="0.1"/>
  </joint>

  <link name="${prefix}Wrist_Pitch_Roll">
    <inertial>
      <origin
        xyz="-0.00852653127372418 -0.0352278997897927 -2.34622481569413E-05"
        rpy="0 0 0" />
      <mass
        value="0.066132067097723" />
      <inertia
        ixx="1.95717492443445E-05"
        ixy="-6.62714374412293E-07"
        ixz="5.20089016442066E-09"
        iyy="2.38028417569933E-05"
        iyz="4.09549055863776E-08"
        izz="3.4540143384536E-05" />
    </inertial>
    <visual>
      <origin
        xyz="0 0 0"
        rpy="0 0 0" />
      <geometry>
        <mesh
          filename="${meshes_file_directory}/Wrist_Pitch_Roll.STL" />
      </geometry>
      <material name="brightyellow" >
        <color rgba="1.0 0.9921568627450981 0.00392156862745098 1.0" />
      </material>
    </visual>
    <collision>
      <origin
        xyz="0 0 0"
        rpy="0 0 0" />
      <geometry>
        <mesh
          filename="${meshes_file_directory}/Wrist_Pitch_Roll.STL" />
      </geometry>
    </collision>
  </link>
  <joint name="${prefix}Wrist_Pitch" type="revolute">
    <origin
      xyz="0 0.0052 0.1349"
      rpy="-1.57079 0 0" />
    <parent
      link="${prefix}Lower_Arm" />
    <child
      link="${prefix}Wrist_Pitch_Roll" />
    <axis
      xyz="1 0 0" />
    <limit effort="1000" lower="-1.658" upper="1.658" velocity="5.0"/>
    <dynamics damping="0.1"/>
  </joint>

  <link name="${prefix}Fixed_Gripper">
    <inertial>
      <origin
        xyz="0.00552376906426563 -0.0280167153359021 0.000483582592841092"
        rpy="0 0 0" />
      <mass
        value="0.0929859131176897" />
      <inertia
        ixx="4.3328249304211E-05"
        ixy="7.09654328670947E-06"
        ixz="5.99838530879484E-07"
        iyy="3.04451747368212E-05"
        iyz="-1.58743247545413E-07"
        izz="5.02460913506734E-05" />
    </inertial>
    <visual>
      <origin
        xyz="0 0 0"
        rpy="0 0 0" />
      <geometry>
        <mesh
          filename="${meshes_file_directory}/Fixed_Gripper.STL" />
      </geometry>
      <material name="brightyellow" >
        <color rgba="1.0 0.9921568627450981 0.00392156862745098 1.0" />
      </material>
    </visual>
    <collision>
      <origin
        xyz="0 0 0"
        rpy="0 0 0" />
      <geometry>
        <mesh
          filename="${meshes_file_directory}/Fixed_Gripper.STL" />
      </geometry>
    </collision>
  </link>
  <joint name="${prefix}Wrist_Roll" type="revolute">
    <origin
      xyz="0 -0.0601 0"
      rpy="0 1.57079 0" />
    <parent
      link="${prefix}Wrist_Pitch_Roll" />
    <child
      link="${prefix}Fixed_Gripper" />
    <axis
      xyz="0 1 0" />
    <limit effort="1000" lower="-2.75" upper="2.75" velocity="5.0"/>
    <dynamics damping="0.1"/>
  </joint>

  <link name="${prefix}Moving_Jaw">
    <inertial>
      <origin
        xyz="-0.00161744605468241 -0.0303472584046471 0.000449645961853651"
        rpy="0 0 0" />
      <mass
        value="0.0202443794940372" />
      <inertia
        ixx="1.10911325081525E-05"
        ixy="-5.35076503033314E-07"
        ixz="-9.46105662101403E-09"
        iyy="3.03576451001973E-06"
        iyz="-1.71146075110632E-07"
        izz="8.9916083370498E-06" />
    </inertial>
    <visual>
      <origin
        xyz="0 0 0"
        rpy="0 0 0" />
      <geometry>
        <mesh
          filename="${meshes_file_directory}/Moving_Jaw.STL" />
      </geometry>
      <material name="brightyellow" >
        <color rgba="1.0 0.9921568627450981 0.00392156862745098 1.0" />
      </material>
    </visual>
    <collision>
      <origin
        xyz="0 0 0"
        rpy="0 0 0" />
      <geometry>
        <mesh
          filename="${meshes_file_directory}/Moving_Jaw.STL" />
      </geometry>
    </collision>
  </link>
  <joint name="${prefix}Gripper" type="revolute">
    <origin
      xyz="-0.0202 -0.0244 0"
      rpy="3.1416 0 3.1416" />
    <parent
      link="${prefix}Fixed_Gripper" />
    <child
      link="${prefix}Moving_Jaw" />
    <axis
      xyz="0 0 1" />
    <limit effort="1000" lower="-0.1792" upper="1.5708" velocity="5.0"/>
    <dynamics damping="0.1"/>
  </joint>

  <link name="${prefix}End_Effector">
    <visual>
      <origin xyz="0 0 0" rpy="0 0 0"/>
      <geometry>
        <box size="0.01 0.01 0.01" />
      </geometry>
      <material name="red">
        <color rgba="1.0 0.0 0.0 1"/>
      </material>
    </visual>
  </link>
  <joint name="${prefix}End_Effector_Joint" type="fixed">
    <parent link="${prefix}Fixed_Gripper"/>
    <child link="${prefix}End_Effector"/>
    <origin xyz="0.0 -0.09 0.0" rpy="0 0 0"/>
  </joint>

  </xacro:macro>
</robot>